File: Synthesis of barbituric acid doped carbon nitride for efficient solar-driven photocatalytic degradation of aniline/data/CN-BA-XPS/分峰 - 副本/XPS分峰软件XPSpeak41/VAMASmult.txt
VAMAS Surface Chemical Analysis Standard Data Transfer Format 1988 May 4
V G Scientific Ltd
Ecsalab
Akmal Bhutta
99010703.DAT;1
3
Pt (773K) (as received)


NORM
REGULAR
7
0
0
0
0
0
7
New Block
Sample ID
1999
1
7
14
56
42
0
0
XPS
Mg Source
1253.60
0.00
0
0
0
0
FAT
50.00
0
4.39
0.00
0
0
0
0
SURVEY
SURVEY
-1
Binding eV
eV
0.00
0.50
1
Counts
d
pulse counting
0.20
0
0
0
132
159
168
145
166
164
135
181
183
181
212
221
256
266
263
247
239
261
241
208
232
239
216
212
229
204
213
231
322
437
444
481
395
362
294
310
292
240
251
265
260
236
261
223
267
233
242
260
268
287
281
265
296
303
307
308
287
283
299
312
340
278
297
306
318
291
320
299
345
349
393
455
508
464
428
404
440
606
800
921
1597
2284
1849
991
533
499
472
439
451
474
468
499
505
508
568
522
553
579
605
648
608
674
630
721
724
693
687
719
709
691
716
696
643
654
670
760
783
838
774
750
703
764
764
929
1249
1762
2131
1818
1231
860
732
690
699
722
744
710
753
744
758
764
794
870
827
782
840
905
847
908
903
907
935
894
925
887
888
858
846
827
853
798
861
853
820
819
837
829
832
807
797
817
810
793
797
814
855
798
801
851
822
805
807
785
789
835
769
789
833
839
825
828
812
796
790
811
824
846
798
810
790
840
786
805
805
789
806
840
819
836
779
829
789
788
783
812
828
847
798
832
859
791
791
835
762
804
815
793
800
785
772
792
745
779
862
774
816
812
797
821
816
845
850
852
776
803
791
775
827
828
865
776
782
775
819
750
809
742
817
833
803
780
788
809
814
799
784
779
766
775
821
837
906
851
841
928
861
846
831
842
804
818
863
952
919
973
911
905
918
1008
1099
1172
1531
2247
2219
1574
1170
1079
954
986
964
903
936
961
956
1036
985
1122
1060
1070
1023
1050
1058
1069
1077
1079
1118
1024
1092
1121
1132
1172
1180
1267
1162
1185
1164
1148
1133
1131
1156
1165
1103
1109
1156
1077
1107
1210
1159
1141
1202
1169
1204
1166
1103
1096
1172
1095
1139
1159
1102
1089
1114
1104
1108
1111
1099
1093
1042
1121
1127
1109
1135
1042
1098
1045
1096
1064
1077
1057
1056
1096
1116
1067
1156
1111
1045
1106
1079
1050
1059
1064
1074
1052
1066
1125
1106
1114
1047
1125
1082
1058
1077
1132
1057
1082
1069
1116
1149
1111
1071
1061
1145
1085
1056
1063
1077
1060
1134
1077
1072
1110
1042
1120
1095
1095
1057
1076
1025
1083
1058
1075
1077
1029
1090
1104
1079
1067
1052
1038
1077
1066
1039
990
1116
1066
1114
1049
1054
1136
1103
1084
1102
1037
1094
1072
1071
1043
1109
1060
1054
1084
1121
1048
1087
1131
1045
1054
1137
1081
1097
1118
1043
1110
1058
1028
1099
1089
1050
1103
1064
1051
1073
1089
1082
1060
1088
1082
1181
1063
1080
1143
1037
1098
1112
1049
1098
1086
1124
1123
1106
1167
1155
1170
1099
1171
1152
1166
1130
1142
1116
1163
1088
1058
1138
1018
1121
1141
1106
1145
1179
1158
1179
1177
1170
1129
1126
1207
1227
1209
1234
1192
1302
1330
1306
1266
1254
1345
1555
1740
2049
2251
2046
1779
1552
1472
1696
2382
4287
7865
9684
8103
4626
2501
1735
1615
1630
1577
1697
1721
1910
2008
2060
2255
2393
2535
2477
2615
2812
2869
2966
3004
3087
3376
3419
3432
3379
3303
3136
3031
2830
2783
2715
2783
2856
2832
2740
2854
2826
2888
2859
2824
2931
2896
2959
2988
3013
2899
2968
3102
2938
2961
2994
3014
2993
2984
2897
2968
2960
2825
2946
2941
2871
2929
2896
2812
2908
2992
2891
3027
2886
2994
2991
2945
3107
2965
2849
2904
3008
2945
2965
2921
3010
2916
2966
2980
3042
2885
2956
2967
2932
2977
2904
2880
2869
2966
2985
2840
2869
2970
2939
2956
2984
2989
2905
2956
3031
2915
2978
2952
2917
2855
2870
2906
2934
2808
2871
3007
2889
3032
2904
2993
2914
2947
2829
2916
2763
2967
2860
2933
2902
2828
2929
2918
2921
2861
3042
3044
2966
2989
2853
2887
2992
2887
2888
2938
2949
2903
2967
2932
2937
3018
3025
2961
2951
2937
2904
2876
2986
3036
3003
2929
2941
2829
2935
2903
2900
2972
3040
2886
3002
2951
3005
2914
2959
2853
2916
3077
2889
2869
3001
2936
2957
2981
2941
2956
2948
3006
3162
3089
2943
3052
2964
2919
2964
2955
2888
3076
3027
3138
3154
3208
3252
3532
3768
3927
4073
4476
4503
4696
5062
5367
5855
6425
6901
6921
6671
5940
5422
4932
4680
4383
4557
4489
4439
4533
4653
4718
4787
5017
5053
5143
5413
5747
5907
5973
5843
5682
5722
5580
5472
5411
5305
5317
5302
5203
5172
5217
5422
5433
5530
5394
5412
5408
5464
5267
5450
5346
5282
5298
5358
5313
5550
5270
5222
5304
5214
5132
5246
5267
5298
5315
5371
5271
5317
5255
5272
5279
5189
5235
5313
5161
5111
5161
5263
5153
5222
5225
5063
5256
5217
5182
5319
5157
5246
5199
5081
5203
5082
5302
5238
5197
5115
5175
5267
5360
5331
5317
5266
5316
5224
5207
5209
5156
5121
5088
5271
5155
5210
5172
5184
5214
5319
5288
5207
5237
5243
5207
5134
5204
5177
5151
5295
5261
5356
5186
5074
5308
5299
5210
5229
5249
5160
5235
5235
5369
5186
5347
5279
5364
5242
5288
5216
5202
5294
5294
5347
5349
5212
5284
5271
5317
5297
5286
5233
5399
5370
5414
5250
5396
5272
5239
5296
5424
5378
5367
5315
5442
5241
5383
5285
5353
5455
5453
5403
5266
5374
5233
5404
5383
5398
5374
5325
5327
5460
5387
5333
5410
5401
5385
5407
5490
5500
5494
5427
5553
5342
5562
5626
5577
5552
5623
5517
5512
5636
5650
5587
5517
5511
5540
5486
5527
5623
5600
5620
5627
5424
5564
5640
5675
5731
5505
5700
5740
5796
5647
5718
5611
5609
5636
5826
5728
5755
5750
5871
5670
5800
5887
6060
5970
6009
6421
6395
6365
6800
6585
6747
6881
6835
7049
6801
7044
7074
6962
New Block
Sample ID
1999
1
7
14
56
42
0
0
XPS
Mg Source
1253.60
0.00
0
0
0
0
FAT
20.00
0
4.84
0.00
0
0
0
0
Sulphur
Sulphur
-1
Binding eV
eV
160.00
0.05
1
Counts
d
pulse counting
0.50
10
0
0
0
0
0
361
1940
2218
2164
2072
2064
2158
2072
2052
2056
2090
2073
2145
2046
2015
2086
2058
2045
2055
2017
2123
2121
2033
2015
2036
2081
2131
1998
2030
2070
2072
2027
2082
2109
2072
2086
2066
2093
2111
2118
2109
2094
2069
2050
2075
2030
2101
2031
2069
2115
2055
2086
2064
2033
2110
2150
2144
2059
2059
2131
1990
2002
2025
2025
2109
2061
1998
2084
2019
2057
2114
2076
2045
2036
2134
2043
2061
2110
2076
2058
2027
2130
2067
2108
2109
2117
2064
1998
2174
1978
2165
2157
2154
2006
2037
2058
2099
2182
2027
2179
2034
2033
1995
2128
2008
2105
2116
2006
2038
2088
1976
2138
2104
2059
2127
2138
2028
2053
1974
2086
2018
2218
2074
2117
2091
2097
2104
2069
2137
2066
2162
2109
2123
2037
2007
2055
2072
1953
2035
2062
2083
2053
2053
2046
1984
2082
2018
2067
2095
2074
2089
2040
1990
2034
2081
2019
2012
2061
2057
2012
2139
2069
2052
2037
2032
2114
2135
2056
2000
2025
2017
2125
2083
1940
2130
2032
2061
2190
2177
2065
2135
2130
1998
2101
2131
2022
2106
2082
2184
2056
1977
2033
2095
2078
2044
2142
2071
2051
2036
2082
2129
2077
2033
2079
2098
2045
2106
2029
2092
2111
2056
2098
2101
2081
2129
2068
2098
2037
2007
2105
2084
2085
2088
2113
2032
2124
2068
2067
2133
2012
2078
2041
2071
2052
2081
2056
2124
2062
2052
2097
2036
2043
2126
2012
2179
2050
2022
2151
2140
2107
2050
2079
2143
1999
2026
2120
2057
2007
2046
2063
2142
2088
2094
2106
2066
2098
2118
2066
2110
2051
2091
2061
2102
2006
2046
2050
2101
2089
2041
2116
2067
2173
2051
2111
1999
2022
2012
2120
2091
2111
2079
2097
2081
2089
2064
2102
2004
2020
2093
1967
2061
2042
2133
2105
2123
2071
2083
2115
2076
2080
2110
2148
2016
2085
2169
2106
2079
2144
2091
2097
1999
2055
2000
2100
2033
2116
1950
2090
2114
2124
2056
2082
2056
2022
1982
2072
2085
2118
2117
2014
2130
2146
2085
2072
2103
2037
2091
2081
2161
2064
2018
2107
2063
2033
2017
2030
2136
2114
2051
2008
2046
2138
2053
2010
New Block
Sample ID
1999
1
7
14
56
42
0
0
XPS
Mg Source
1253.60
0.00
0
0
0
0
FAT
20.00
0
4.84
0.00
0
0
0
0
Carbon
Carbon
-1
Binding eV
eV
280.00
0.05
1
Counts
d
pulse counting
0.50
5
0
0
0
0
0
321
1064
3468
1186
1181
1283
1222
1155
1199
1261
1229
1230
1277
1246
1257
1201
1268
1263
1181
1302
1245
1212
1288
1328
1225
1240
1314
1249
1234
1279
1319
1318
1287
1299
1239
1275
1296
1273
1302
1263
1260
1222
1246
1359
1249
1259
1174
1235
1254
1205
1153
1223
1231
1316
1240
1236
1197
1193
1140
1177
1211
1125
1242
1194
1136
1151
1142
1131
1137
1064
1139
1111
1194
1171
1128
1116
1143
1109
1154
1136
1139
1198
1150
1202
1116
1122
1111
1132
1113
1122
1092
1099
1176
1113
1121
1150
1165
1168
1105
1201
1172
1119
1100
1111
1202
1126
1159
1151
1166
1258
1205
1153
1119
1109
1136
1287
1195
1213
1270
1182
1200
1270
1196
1210
1235
1217
1267
1300
1244
1285
1288
1295
1302
1278
1272
1295
1271
1356
1381
1372
1397
1448
1379
1439
1420
1458
1451
1339
1433
1424
1532
1456
1578
1499
1485
1565
1594
1535
1587
1662
1528
1621
1687
1625
1614
1727
1654
1709
1804
1775
1738
1831
1950
1863
1939
1912
1954
1974
2049
2014
2111
2160
2235
2287
2250
2330
2432
2518
2463
2639
2558
2739
2734
2791
2860
2870
2998
3014
3126
3058
3201
3333
3352
3176
3349
3457
3312
3350
3369
3441
3468
3333
3419
3438
3255
3308
3261
3273
3221
3200
3167
3134
3057
2966
2824
2797
2717
2766
2578
2654
2584
2535
2345
2269
2256
2260
2147
2147
2104
1873
1960
1859
1831
1769
1711
1706
1646
1672
1526
1545
1548
1525
1485
1497
1434
1522
1434
1399
1344
1378
1373
1324
1368
1381
1347
1341
1330
1334
1265
1250
1323
1257
1311
1320
1282
1338
1237
1313
1306
1237
1319
1319
1256
1297
1230
1299
1332
1285
1280
1341
1302
1247
1292
1269
1267
1362
1303
1358
1237
1272
1332
1329
1230
1277
1281
1252
1344
1318
1222
1231
1239
1246
1296
1254
1201
1239
1275
1281
1239
1249
1218
1194
1256
1303
New Block
Sample ID
1999
1
7
14
56
42
0
0
XPS
Mg Source
1253.60
0.00
0
0
0
0
FAT
20.00
0
4.84
0.00
0
0
0
0
Oxygen
Oxygen
-1
Binding eV
eV
530.00
0.05
1
Counts
d
pulse counting
0.50
5
0
0
0
0
0
281
1870
13138
2122
2115
2095
2162
2086
2015
2017
2056
1971
1950
1962
1919
2088
2030
1952
1984
1954
1942
1933
1913
1979
1910
1879
2018
1962
1974
1974
1922
1897
2030
2057
1961
1898
1940
1962
1979
1950
1909
1870
1982
1956
1925
1925
1944
1930
1963
1976
2010
2064
2096
2025
2034
1998
2081
2069
2173
2035
2117
2117
2226
2201
2276
2199
2217
2249
2300
2350
2410
2358
2386
2528
2508
2597
2534
2646
2732
2680
2766
2971
3003
3058
3180
3224
3294
3402
3410
3665
3740
3858
3983
4047
4346
4403
4562
4780
5067
5213
5451
5582
5745
5901
6158
6349
6613
6975
7124
7244
7670
7993
8295
8530
8799
9160
9327
9613
9785
10052
10204
10609
11005
11247
11393
11683
11704
11878
12228
12349
12475
12584
12719
12818
12793
13051
13138
12862
13047
13113
12949
12860
12840
12868
12501
12616
12451
12348
12028
11979
11751
11640
11325
11231
10998
10682
10646
10087
9826
9785
9262
9097
8779
8734
8362
8170
7955
7714
7508
7212
7007
6590
6537
6457
6020
5911
5710
5474
5162
5067
4956
4753
4601
4457
4347
3993
4082
3815
3711
3693
3479
3387
3332
3239
3104
3148
3039
2982
2799
2775
2813
2706
2589
2484
2623
2534
2454
2511
2443
2351
2323
2393
2338
2309
2188
2136
2204
2160
2222
2110
2163
2171
2141
2089
2043
2156
2026
2060
2133
2114
2011
2017
2065
2038
2096
2061
2109
1969
2115
2002
2079
2066
1991
2054
1978
2060
2075
1991
1930
1979
2063
1975
2013
2114
2018
1987
2043
2009
2012
2025
2028
2012
2034
2039
1956
2032
2053
2070
2098
2038
2019
2033
2071
2083
2058
2159
2037
2115
2036
1995
2058
2025
2008
2122
New Block
Sample ID
1999
1
7
14
56
42
0
0
XPS
Mg Source
1253.60
0.00
0
0
0
0
FAT
20.00
0
4.84
0.00
0
0
0
0
Platinum
Platinum
-1
Binding eV
eV
315.00
0.05
1
Counts
d
pulse counting
0.50
15
0
0
0
0
0
301
4204
5011
4411
4469
4539
4345
4390
4509
4371
4259
4329
4351
4487
4333
4461
4457
4415
4520
4473
4455
4436
4471
4292
4477
4486
4468
4500
4372
4442
4472
4525
4490
4562
4492
4651
4439
4564
4432
4642
4485
4554
4674
4533
4436
4593
4497
4526
4616
4660
4606
4572
4515
4488
4585
4709
4553
4617
4714
4567
4680
4669
4716
4561
4666
4724
4848
4769
4701
4653
4826
4641
4913
4781
4753
4802
4758
4823
4784
4721
4743
4867
4894
4835
4791
4847
4705
4810
4855
4739
4730
4861
4770
4755
5011
4864
4877
4873
4680
4947
4845
4882
4770
4837
4874
4814
4856
4923
4806
4980
4750
4800
4880
4839
4864
4824
4814
4705
4816
4872
4904
4735
4656
4786
4830
4730
4721
4865
4689
4626
4842
4710
4735
4606
4623
4831
4683
4873
4720
4708
4752
4605
4680
4762
4736
4659
4555
4776
4625
4777
4560
4447
4576
4538
4611
4546
4636
4526
4514
4658
4557
4638
4524
4528
4570
4619
4494
4631
4557
4512
4583
4505
4543
4396
4494
4549
4575
4498
4435
4506
4572
4525
4604
4685
4443
4495
4541
4467
4433
4443
4540
4391
4468
4599
4510
4471
4405
4523
4607
4490
4409
4409
4584
4446
4527
4602
4609
4474
4458
4410
4537
4540
4436
4422
4479
4538
4616
4390
4565
4374
4529
4434
4453
4455
4459
4468
4467
4466
4555
4448
4482
4402
4553
4498
4509
4439
4425
4435
4421
4447
4417
4436
4516
4564
4554
4493
4387
4521
4447
4509
4424
4422
4495
4355
4358
4438
4470
4504
4204
4573
4430
4376
4437
4660
4409
4519
4445
4393
4395
4342
4507
4439
4415
4363
4389
4419
4328
4449
4438
4460
4309
4469
4403
4365
4311
4352
4334
4553
4382
4395
4405
4403
4384
4411
4427
4556
4420
4331
4515
4345
4318
4485
4414
4440
New Block
Sample ID
1999
1
7
14
56
42
0
0
XPS
Mg Source
1253.60
0.00
0
0
0
0
FAT
20.00
0
4.84
0.00
0
0
0
0
Al and Pt
Al and Pt
-1
Binding eV
eV
70.00
0.05
1
Counts
d
pulse counting
0.50
5
0
0
0
0
0
401
458
3175
568
586
560
595
570
614
619
634
666
641
602
595
654
605
601
596
606
617
594
599
637
619
660
630
613
611
661
639
618
675
633
603
621
639
612
649
607
606
589
564
600
605
577
556
566
568
518
558
532
538
514
525
561
504
541
512
514
499
507
496
517
481
500
485
460
508
478
512
500
491
466
460
458
487
482
469
488
462
479
485
478
543
476
503
505
487
530
524
521
499
562
557
508
526
533
539
541
583
628
559
614
599
600
650
592
623
657
724
639
655
690
687
740
779
744
764
776
797
831
883
844
895
857
917
901
923
908
929
935
1004
962
988
987
992
997
968
1047
1032
1055
1018
1021
1033
1017
1030
1009
992
1030
1046
1035
988
1016
1037
1067
1041
1123
1057
1090
1079
1186
1199
1246
1203
1287
1331
1333
1370
1402
1445
1464
1521
1583
1675
1624
1685
1809
1868
1950
1993
2046
2119
2147
2275
2389
2302
2546
2515
2597
2711
2811
2868
2896
2944
3011
2992
3011
3020
3028
3062
3062
3175
3122
3001
3070
3047
2950
2953
2953
2858
2867
2712
2726
2688
2652
2542
2462
2340
2298
2219
2230
1998
2037
1987
1912
1742
1758
1693
1496
1513
1427
1381
1268
1267
1250
1261
1136
1125
1044
971
971
963
980
929
852
858
771
780
777
744
756
702
693
728
695
665
661
655
717
611
625
649
655
628
590
637
613
557
617
581
584
606
603
592
588
547
616
602
609
601
577
580
597
577
561
550
577
541
563
561
573
591
556
558
549
551
582
585
556
572
597
574
566
537
606
549
520
564
571
554
555
524
544
531
506
591
533
547
584
541
546
492
539
527
518
567
572
530
527
596
549
572
541
562
560
514
549
568
553
573
585
571
566
571
537
550
579
558
574
519
565
564
556
543
573
574
528
535
545
550
561
571
548
568
568
563
545
563
565
549
582
553
547
549
554
563
613
551
559
580
549
575
564
606
553
574
570
553
582
594
544
525
582
573
625
584
598
558
557
562
627
619
550
New Block
Sample ID
1999
1
7
14
56
42
0
0
XPS
Mg Source
1253.60
0.00
0
0
0
0
FAT
20.00
0
4.84
0.00
0
0
0
0
Aluminium
Aluminium
-1
Binding eV
eV
118.00
0.05
1
Counts
d
pulse counting
0.50
5
0
0
0
0
0
241
837
2859
894
934
867
879
846
911
885
911
874
849
887
872
852
873
877
877
883
839
837
869
887
888
848
888
849
875
863
871
879
898
914
857
840
876
969
933
904
856
883
900
887
911
889
930
959
927
950
892
977
927
922
930
948
941
932
966
926
937
996
974
980
1011
895
921
999
933
1022
1018
1024
1053
1021
1001
1078
1075
1096
1077
1159
1106
1157
1120
1095
1158
1161
1226
1195
1220
1225
1245
1221
1323
1201
1336
1362
1334
1294
1503
1474
1480
1469
1573
1537
1573
1661
1644
1653
1698
1796
1813
1897
1909
1925
2078
2034
1993
2150
2079
2193
2267
2285
2316
2300
2360
2427
2428
2635
2490
2619
2759
2694
2675
2681
2738
2806
2631
2839
2859
2811
2766
2801
2751
2740
2827
2739
2768
2722
2646
2628
2502
2580
2616
2498
2504
2403
2408
2317
2300
2203
2128
2103
2069
2075
1992
1973
1866
1844
1789
1773
1747
1655
1714
1560
1626
1523
1517
1404
1397
1368
1287
1334
1283
1302
1305
1263
1193
1167
1191
1143
1122
1171
1086
1102
1093
1022
1088
1043
1019
1022
1012
936
1025
957
990
953
985
929
1014
964
919
962
953
920
977
861
952
988
904
958
890
956
904
911
879
958
888
911
849
875
892
891
901
900
892
881
878
846
909
866
893
837
862
891
end of experiment